multiprocessing.pool.RemoteTraceback: 
"""
Traceback (most recent call last):
  File "/home/bcheng/workspace/tools/anaconda3/envs/cvxpy/lib/python3.12/multiprocessing/pool.py", line 125, in worker
    result = (True, func(*args, **kwds))
                    ^^^^^^^^^^^^^^^^^^^
  File "/home/bcheng/workspace/tools/anaconda3/envs/cvxpy/lib/python3.12/multiprocessing/pool.py", line 48, in mapstar
    return list(map(*args))
           ^^^^^^^^^^^^^^^^
  File "/home/bcheng/workspace/dev/cvxpy/ex4/main.py", line 10, in prox
    f += (rho/2)*sum_squares(x - v)
          ^^^
NameError: name 'rho' is not defined
"""

The above exception was the direct cause of the following exception:

Traceback (most recent call last):
  File "/home/bcheng/workspace/dev/cvxpy/ex4/main.py", line 48, in <module>
    main()
  File "/home/bcheng/workspace/dev/cvxpy/ex4/main.py", line 37, in main
    xi = pool.map(prox, zip(funcs, prox_args))
         ^^^^^^^^^^^^^^^^^^^^^^^^^^^^^^^^^^^^^
  File "/home/bcheng/workspace/tools/anaconda3/envs/cvxpy/lib/python3.12/multiprocessing/pool.py", line 367, in map
    return self._map_async(func, iterable, mapstar, chunksize).get()
           ^^^^^^^^^^^^^^^^^^^^^^^^^^^^^^^^^^^^^^^^^^^^^^^^^^^^^^^^^
  File "/home/bcheng/workspace/tools/anaconda3/envs/cvxpy/lib/python3.12/multiprocessing/pool.py", line 774, in get
    raise self._value
NameError: name 'rho' is not defined
