multiprocessing.pool.RemoteTraceback: 
"""
Traceback (most recent call last):
  File "/home/bcheng/workspace/tools/anaconda3/envs/cvxpy/lib/python3.12/multiprocessing/pool.py", line 125, in worker
    result = (True, func(*args, **kwds))
                    ^^^^^^^^^^^^^^^^^^^
  File "/home/bcheng/workspace/tools/anaconda3/envs/cvxpy/lib/python3.12/multiprocessing/pool.py", line 48, in mapstar
    return list(map(*args))
           ^^^^^^^^^^^^^^^^
  File "/home/bcheng/workspace/dev/cvxpy/ex4/main.py", line 20, in prox
    Problem(Minimize(f)).solve()
  File "/home/bcheng/workspace/tools/anaconda3/envs/cvxpy/lib/python3.12/site-packages/cvxpy/problems/problem.py", line 503, in solve
    return solve_func(self, *args, **kwargs)
           ^^^^^^^^^^^^^^^^^^^^^^^^^^^^^^^^^
  File "/home/bcheng/workspace/tools/anaconda3/envs/cvxpy/lib/python3.12/site-packages/cvxpy/problems/problem.py", line 1073, in _solve
    data, solving_chain, inverse_data = self.get_problem_data(
                                        ^^^^^^^^^^^^^^^^^^^^^^
  File "/home/bcheng/workspace/tools/anaconda3/envs/cvxpy/lib/python3.12/site-packages/cvxpy/problems/problem.py", line 696, in get_problem_data
    data, inverse_data = solving_chain.apply(self, verbose)
                         ^^^^^^^^^^^^^^^^^^^^^^^^^^^^^^^^^^
  File "/home/bcheng/workspace/tools/anaconda3/envs/cvxpy/lib/python3.12/site-packages/cvxpy/reductions/chain.py", line 76, in apply
    problem, inv = r.apply(problem)
                   ^^^^^^^^^^^^^^^^
  File "/home/bcheng/workspace/tools/anaconda3/envs/cvxpy/lib/python3.12/site-packages/cvxpy/reductions/qp2quad_form/qp_matrix_stuffing.py", line 258, in apply
    params_to_P, params_to_q, flattened_variable = self.stuffed_objective(
                                                   ^^^^^^^^^^^^^^^^^^^^^^^
  File "/home/bcheng/workspace/tools/anaconda3/envs/cvxpy/lib/python3.12/site-packages/cvxpy/reductions/qp2quad_form/qp_matrix_stuffing.py", line 243, in stuffed_objective
    params_to_P, params_to_q = extractor.quad_form(expr)
                               ^^^^^^^^^^^^^^^^^^^^^^^^^
  File "/home/bcheng/workspace/tools/anaconda3/envs/cvxpy/lib/python3.12/site-packages/cvxpy/utilities/coeff_extractor.py", line 259, in quad_form
    raise ValueError("Resulting quadratic form does not have "
ValueError: Resulting quadratic form does not have appropriate dimensions
"""

The above exception was the direct cause of the following exception:

Traceback (most recent call last):
  File "/home/bcheng/workspace/dev/cvxpy/ex4/main.py", line 33, in <module>
    xi = pool.map(prox, zip(funcs, prox_args))
         ^^^^^^^^^^^^^^^^^^^^^^^^^^^^^^^^^^^^^
  File "/home/bcheng/workspace/tools/anaconda3/envs/cvxpy/lib/python3.12/multiprocessing/pool.py", line 367, in map
    return self._map_async(func, iterable, mapstar, chunksize).get()
           ^^^^^^^^^^^^^^^^^^^^^^^^^^^^^^^^^^^^^^^^^^^^^^^^^^^^^^^^^
  File "/home/bcheng/workspace/tools/anaconda3/envs/cvxpy/lib/python3.12/multiprocessing/pool.py", line 774, in get
    raise self._value
ValueError: Resulting quadratic form does not have appropriate dimensions
